Loading gpytorch/gpu-cuda-11.6/pytorch-1.11.0/1.8.0
  Loading requirement: cudnn/8.4.1 pytorch/gpu-cuda-11.6/1.11.0
ERROR: Could not find a version that satisfies the requirement scipy.stats (from versions: none)
ERROR: No matching distribution found for scipy.stats
ERROR: Could not find a version that satisfies the requirement scipy.interpolate (from versions: none)
ERROR: No matching distribution found for scipy.interpolate
/mpcdf/soft/SLE_15/packages/skylake/pytorch/gpu-cuda-11.6/anaconda_3_2021.11-2021.11/1.11.0/lib/python3.9/site-packages/torch/functional.py:568: UserWarning: torch.meshgrid: in an upcoming release, it will be required to pass the indexing argument. (Triggered internally at  /home/abuild/rpmbuild/BUILD/pytorch-1.11.0/aten/src/ATen/native/TensorShape.cpp:2227.)
  return _VF.meshgrid(tensors, **kwargs)  # type: ignore[attr-defined]
/mpcdf/soft/SLE_15/packages/skylake/gpytorch/gpu-cuda-11.6/pytorch-1.11.0/anaconda_3_2021.11-2021.11/1.8.0/lib/python3.9/site-packages/gpytorch/lazy/triangular_lazy_tensor.py:136: UserWarning: torch.triangular_solve is deprecated in favor of torch.linalg.solve_triangularand will be removed in a future PyTorch release.
torch.linalg.solve_triangular has its arguments reversed and does not return a copy of one of the inputs.
X = torch.triangular_solve(B, A).solution
should be replaced with
X = torch.linalg.solve_triangular(A, B). (Triggered internally at  /home/abuild/rpmbuild/BUILD/pytorch-1.11.0/aten/src/ATen/native/BatchLinearAlgebra.cpp:1666.)
  res = torch.triangular_solve(right_tensor, self.evaluate(), upper=self.upper).solution
Traceback (most recent call last):
  File "/u/dvoss/al_pmssmwithgp/model/GPmodel2Dnew.py", line 1029, in <module>
    gp_pipeline.plotSlice1D(slice_dim=1, slice_value=0.2, tolerance=0.01, new_x=new_points, save_path=os.path.join(args.output_dir, '1DsliceM1_plot.png'), iteration=args.iteration)
  File "/u/dvoss/al_pmssmwithgp/model/GPmodel2Dnew.py", line 630, in plotSlice1D
    x_true = M_1_filtered[indices_true] # Is marginalized along M_2, so M_1 is x_coordinate
  File "/mpcdf/soft/SLE_15/packages/x86_64/anaconda/3/2021.11/lib/python3.9/site-packages/pandas/core/series.py", line 966, in __getitem__
    return self._get_with(key)
  File "/mpcdf/soft/SLE_15/packages/x86_64/anaconda/3/2021.11/lib/python3.9/site-packages/pandas/core/series.py", line 1001, in _get_with
    return self.loc[key]
  File "/mpcdf/soft/SLE_15/packages/x86_64/anaconda/3/2021.11/lib/python3.9/site-packages/pandas/core/indexing.py", line 931, in __getitem__
    return self._getitem_axis(maybe_callable, axis=axis)
  File "/mpcdf/soft/SLE_15/packages/x86_64/anaconda/3/2021.11/lib/python3.9/site-packages/pandas/core/indexing.py", line 1153, in _getitem_axis
    return self._getitem_iterable(key, axis=axis)
  File "/mpcdf/soft/SLE_15/packages/x86_64/anaconda/3/2021.11/lib/python3.9/site-packages/pandas/core/indexing.py", line 1093, in _getitem_iterable
    keyarr, indexer = self._get_listlike_indexer(key, axis)
  File "/mpcdf/soft/SLE_15/packages/x86_64/anaconda/3/2021.11/lib/python3.9/site-packages/pandas/core/indexing.py", line 1314, in _get_listlike_indexer
    self._validate_read_indexer(keyarr, indexer, axis)
  File "/mpcdf/soft/SLE_15/packages/x86_64/anaconda/3/2021.11/lib/python3.9/site-packages/pandas/core/indexing.py", line 1377, in _validate_read_indexer
    raise KeyError(f"{not_found} not in index")
KeyError: '[2563] not in index'
srun: error: ravg1069: task 0: Exited with exit code 1
srun: Terminating StepId=13212947.0
