Loading gpytorch/gpu-cuda-11.6/pytorch-1.11.0/1.8.0
  Loading requirement: cudnn/8.4.1 pytorch/gpu-cuda-11.6/1.11.0
ERROR: Could not find a version that satisfies the requirement scipy.stats (from versions: none)
ERROR: No matching distribution found for scipy.stats
ERROR: Could not find a version that satisfies the requirement scipy.interpolate (from versions: none)
ERROR: No matching distribution found for scipy.interpolate
/mpcdf/soft/SLE_15/packages/skylake/gpytorch/gpu-cuda-11.6/pytorch-1.11.0/anaconda_3_2021.11-2021.11/1.8.0/lib/python3.9/site-packages/gpytorch/lazy/triangular_lazy_tensor.py:136: UserWarning: torch.triangular_solve is deprecated in favor of torch.linalg.solve_triangularand will be removed in a future PyTorch release.
torch.linalg.solve_triangular has its arguments reversed and does not return a copy of one of the inputs.
X = torch.triangular_solve(B, A).solution
should be replaced with
X = torch.linalg.solve_triangular(A, B). (Triggered internally at  /home/abuild/rpmbuild/BUILD/pytorch-1.11.0/aten/src/ATen/native/BatchLinearAlgebra.cpp:1666.)
  res = torch.triangular_solve(right_tensor, self.evaluate(), upper=self.upper).solution
Traceback (most recent call last):
  File "/mpcdf/soft/SLE_15/packages/x86_64/anaconda/3/2021.11/lib/python3.9/site-packages/pandas/core/indexes/base.py", line 3361, in get_loc
    return self._engine.get_loc(casted_key)
  File "pandas/_libs/index.pyx", line 76, in pandas._libs.index.IndexEngine.get_loc
  File "pandas/_libs/index.pyx", line 108, in pandas._libs.index.IndexEngine.get_loc
  File "pandas/_libs/hashtable_class_helper.pxi", line 5198, in pandas._libs.hashtable.PyObjectHashTable.get_item
  File "pandas/_libs/hashtable_class_helper.pxi", line 5206, in pandas._libs.hashtable.PyObjectHashTable.get_item
KeyError: 'MO_Omega'

The above exception was the direct cause of the following exception:

Traceback (most recent call last):
  File "/u/dvoss/al_pmssmwithgp/model/GPmodelnD.py", line 1258, in <module>
    gp_pipeline.load_additional_data()
  File "/u/dvoss/al_pmssmwithgp/model/GPmodelnD.py", line 144, in load_additional_data
    Omega = al_df['MO_Omega'] # TODO: why is there no MO_Omega?
  File "/mpcdf/soft/SLE_15/packages/x86_64/anaconda/3/2021.11/lib/python3.9/site-packages/pandas/core/frame.py", line 3458, in __getitem__
    indexer = self.columns.get_loc(key)
  File "/mpcdf/soft/SLE_15/packages/x86_64/anaconda/3/2021.11/lib/python3.9/site-packages/pandas/core/indexes/base.py", line 3363, in get_loc
    raise KeyError(key) from err
KeyError: 'MO_Omega'
srun: error: ravg1086: task 0: Exited with exit code 1
srun: Terminating StepId=15272012.0
