Loading gpytorch/gpu-cuda-11.6/pytorch-1.11.0/1.8.0
  Loading requirement: cudnn/8.4.1 pytorch/gpu-cuda-11.6/1.11.0
Traceback (most recent call last):
  File "/mpcdf/soft/SLE_15/packages/x86_64/anaconda/3/2021.11/lib/python3.9/site-packages/pandas/core/indexes/base.py", line 3361, in get_loc
    return self._engine.get_loc(casted_key)
  File "pandas/_libs/index.pyx", line 76, in pandas._libs.index.IndexEngine.get_loc
  File "pandas/_libs/index.pyx", line 108, in pandas._libs.index.IndexEngine.get_loc
  File "pandas/_libs/hashtable_class_helper.pxi", line 5198, in pandas._libs.hashtable.PyObjectHashTable.get_item
  File "pandas/_libs/hashtable_class_helper.pxi", line 5206, in pandas._libs.hashtable.PyObjectHashTable.get_item
KeyError: 'IN_M_2'

The above exception was the direct cause of the following exception:

Traceback (most recent call last):
  File "/u/dvoss/al_pmssmwithgp/model/GPmodel2Dnew.py", line 444, in <module>
    gp_pipeline = GPModelPipeline(
  File "/u/dvoss/al_pmssmwithgp/model/GPmodel2Dnew.py", line 47, in __init__
    self.load_initial_data()
  File "/u/dvoss/al_pmssmwithgp/model/GPmodel2Dnew.py", line 67, in load_initial_data
    self.x_train = torch.stack([torch.tensor(limited_df['IN_M_1'].values[:self.initial_train_points], dtype=torch.float32), torch.tensor(limited_df['IN_M_2'].values[:self.initial_train_points], dtype=torch.float32)], dim=1).to(self.device)
  File "/mpcdf/soft/SLE_15/packages/x86_64/anaconda/3/2021.11/lib/python3.9/site-packages/pandas/core/frame.py", line 3458, in __getitem__
    indexer = self.columns.get_loc(key)
  File "/mpcdf/soft/SLE_15/packages/x86_64/anaconda/3/2021.11/lib/python3.9/site-packages/pandas/core/indexes/base.py", line 3363, in get_loc
    raise KeyError(key) from err
KeyError: 'IN_M_2'
srun: error: ravg1131: task 0: Exited with exit code 1
srun: Terminating StepId=12985537.0
